<?xml version="1.0"?>
<robot name="saibot">
    <link name="base_link">
        <visual>
            <origin xyz="0.0 0.0 0.0" rpy="0.0 0.0 0.0"/>
            <geometry>
                <cylinder radius="0.20" length="0.16"/>
            </geometry>
            <material name="yellow">
                <color rgba="1.0 0.4 0.0 0.5"/>
            </material>
        </visual>
    </link>

    <joint name="left_wheel_joint" type="continuous">
        <origin xyz="0.0 0.19 -0.05" rpy="0.0 0.0 0.0"/>
        <parent link="base_link"/>
        <child link="left_wheel_link"/>
        <axis xyz="0.0 1.0 0.0"/>
    </joint>
    <link name="left_wheel_link">
        <visual>
            <origin xyz="0.0 0.0 0.0" rpy="1.57 0.0 0.0"/>
            <geometry>
                <cylinder radius="0.06" length="0.025"/>
            </geometry>
            <material name="white">
                <color rgba="1.0 1.0 1.0 1.0"/>
            </material>
        </visual>
    </link>

    <joint name="right_wheel_joint" type="continuous">
        <origin xyz="0.0 -0.19 -0.05" rpy="0.0 0.0 0.0"/>
        <parent link="base_link"/>
        <child link="right_wheel_link"/>
        <axis xyz="0.0 1.0 0.0"/>
    </joint>
    <link name="right_wheel_link">
        <visual>
            <origin xyz="0.0 0.0 0.0" rpy="1.57 0.0 0.0"/>
            <geometry>
                <cylinder radius="0.06" length="0.025"/>
            </geometry>
            <material name="white">
                <color rgba="1.0 1.0 1.0 1.0"/>
            </material>
        </visual>
    </link>

    <joint name="front_caster_joint" type="continuous">
        <origin xyz="0.18 0.0 -0.095" rpy="0.0 0.0 0.0"/>
        <parent link="base_link"/>
        <child link="front_caster_link"/>
        <axis xyz="0.0 1.0 0.0"/>
    </joint>
    <link name="front_caster_link">
        <visual>
            <origin xyz="0.0 0.0 0.0" rpy="1.57 0.0 0.0"/>
            <geometry>
                <sphere radius="0.015"/>
            </geometry>
            <material name="black">
                <color rgba="0.0 0.0 0.0 1.0"/>
            </material>
        </visual>
    </link>

    <joint name="back_caster_joint" type="continuous">
        <origin xyz="-0.18 0.0 -0.095" rpy="0.0 0.0 0.0"/>
        <parent link="base_link"/>
        <child link="back_caster_link"/>
        <axis xyz="0.0 1.0 0.0"/>
    </joint>
    <link name="back_caster_link">
        <visual>
            <origin xyz="0.0 0.0 0.0" rpy="1.57 0.0 0.0"/>
            <geometry>
                <sphere radius="0.015"/>
            </geometry>
            <material name="black">
                <color rgba="0.0 0.0 0.0 1.0"/>
            </material>
        </visual>
    </link>

    <joint name="camera_joint" type="fixed">
        <origin xyz="0.17 0.0 0.1" rpy="0.0 0.0 0.0"/>
        <parent link="base_link"/>
        <child link="camera_link"/>
    </joint>
    <link name="camera_link">
        <visual>
            <origin xyz="0.0 0.0 0.0" rpy="0.0 0.0 0.0"/>
            <geometry>
                <box size="0.03 0.04 0.04"/>
            </geometry>
            <material name="black">
                <color rgba="0.0 0.0 0.0 1.0"/>
            </material>
        </visual>
    </link>

    <joint name="laser_joint" type="fixed">
        <origin xyz="0.0 0.0 0.106" rpy="0.0 0.0 0.0"/>
        <parent link="base_link"/>
        <child link="laser_link"/>
    </joint>
    <link name="laser_link">
        <visual>
            <origin xyz="0.0 0.0 0.0" rpy="0.0 0.0 0.0"/>
            <geometry>
                <cylinder radius="0.05" length="0.06"/>
            </geometry>
            <material name="black">
                <color rgba="0.0 0.0 0.0 1.0"/>
            </material>
        </visual>
    </link>

    <joint name="kinect_joint" type="fixed">
        <origin xyz="-0.17 0.0 0.115" rpy="0.0 0.0 -1.57"/>
        <parent link="base_link"/>
        <child link="kinect_link"/>
    </joint>
    <link name="kinect_link">
        <visual>
            <origin xyz="0.0 0.0 0.0" rpy="0.0 0.0 0.0"/>
            <geometry>
                <mesh filename="package://lesson7_urdf/meshes/kinect.dae" />
            </geometry>
        </visual>
    </link>
</robot>